[2022-04-28 01:10:04,021] {taskinstance.py:1032} INFO - Dependencies all met for <TaskInstance: local_2_gcs_2_bq_dag.people_local_to_gcs_task scheduled__2022-04-28T00:00:00+00:00 [queued]>
[2022-04-28 01:10:04,090] {taskinstance.py:1032} INFO - Dependencies all met for <TaskInstance: local_2_gcs_2_bq_dag.people_local_to_gcs_task scheduled__2022-04-28T00:00:00+00:00 [queued]>
[2022-04-28 01:10:04,092] {taskinstance.py:1238} INFO - 
--------------------------------------------------------------------------------
[2022-04-28 01:10:04,093] {taskinstance.py:1239} INFO - Starting attempt 1 of 2
[2022-04-28 01:10:04,094] {taskinstance.py:1240} INFO - 
--------------------------------------------------------------------------------
[2022-04-28 01:10:04,154] {taskinstance.py:1259} INFO - Executing <Task(PythonOperator): people_local_to_gcs_task> on 2022-04-28 00:00:00+00:00
[2022-04-28 01:10:04,189] {standard_task_runner.py:52} INFO - Started process 250 to run task
[2022-04-28 01:10:04,220] {standard_task_runner.py:76} INFO - Running: ['***', 'tasks', 'run', 'local_2_gcs_2_bq_dag', 'people_local_to_gcs_task', 'scheduled__2022-04-28T00:00:00+00:00', '--job-id', '10', '--raw', '--subdir', 'DAGS_FOLDER/download_2_gcs_dag_V2.py', '--cfg-path', '/tmp/tmpoyu0znok', '--error-file', '/tmp/tmppw2vgz3e']
[2022-04-28 01:10:04,231] {standard_task_runner.py:77} INFO - Job 10: Subtask people_local_to_gcs_task
[2022-04-28 01:10:04,496] {logging_mixin.py:109} INFO - Running <TaskInstance: local_2_gcs_2_bq_dag.people_local_to_gcs_task scheduled__2022-04-28T00:00:00+00:00 [running]> on host 130e3b0cefbc
[2022-04-28 01:10:04,816] {taskinstance.py:1426} INFO - Exporting the following env vars:
AIRFLOW_CTX_DAG_OWNER=***
AIRFLOW_CTX_DAG_ID=local_2_gcs_2_bq_dag
AIRFLOW_CTX_TASK_ID=people_local_to_gcs_task
AIRFLOW_CTX_EXECUTION_DATE=2022-04-28T00:00:00+00:00
AIRFLOW_CTX_DAG_RUN_ID=scheduled__2022-04-28T00:00:00+00:00
[2022-04-28 01:10:05,373] {taskinstance.py:1700} ERROR - Task failed with exception
Traceback (most recent call last):
  File "/home/airflow/.local/lib/python3.7/site-packages/google/cloud/storage/blob.py", line 2594, in upload_from_file
    retry=retry,
  File "/home/airflow/.local/lib/python3.7/site-packages/google/cloud/storage/blob.py", line 2412, in _do_upload
    retry=retry,
  File "/home/airflow/.local/lib/python3.7/site-packages/google/cloud/storage/blob.py", line 2237, in _do_resumable_upload
    retry=retry,
  File "/home/airflow/.local/lib/python3.7/site-packages/google/cloud/storage/blob.py", line 2112, in _initiate_resumable_upload
    timeout=timeout,
  File "/home/airflow/.local/lib/python3.7/site-packages/google/resumable_media/requests/upload.py", line 421, in initiate
    retriable_request, self._get_status_code, self._retry_strategy
  File "/home/airflow/.local/lib/python3.7/site-packages/google/resumable_media/requests/_request_helpers.py", line 147, in wait_and_retry
    response = func()
  File "/home/airflow/.local/lib/python3.7/site-packages/google/resumable_media/requests/upload.py", line 416, in retriable_request
    self._process_initiate_response(result)
  File "/home/airflow/.local/lib/python3.7/site-packages/google/resumable_media/_upload.py", line 503, in _process_initiate_response
    callback=self._make_invalid,
  File "/home/airflow/.local/lib/python3.7/site-packages/google/resumable_media/_helpers.py", line 104, in require_status_code
    *status_codes
google.resumable_media.common.InvalidResponse: ('Request failed with status code', 404, 'Expected one of', <HTTPStatus.OK: 200>, <HTTPStatus.CREATED: 201>)

During handling of the above exception, another exception occurred:

Traceback (most recent call last):
  File "/home/airflow/.local/lib/python3.7/site-packages/airflow/models/taskinstance.py", line 1329, in _run_raw_task
    self._execute_task_with_callbacks(context)
  File "/home/airflow/.local/lib/python3.7/site-packages/airflow/models/taskinstance.py", line 1455, in _execute_task_with_callbacks
    result = self._execute_task(context, self.task)
  File "/home/airflow/.local/lib/python3.7/site-packages/airflow/models/taskinstance.py", line 1511, in _execute_task
    result = execute_callable(context=context)
  File "/home/airflow/.local/lib/python3.7/site-packages/airflow/operators/python.py", line 174, in execute
    return_value = self.execute_callable()
  File "/home/airflow/.local/lib/python3.7/site-packages/airflow/operators/python.py", line 185, in execute_callable
    return self.python_callable(*self.op_args, **self.op_kwargs)
  File "/opt/airflow/dags/download_2_gcs_dag_V2.py", line 48, in upload_to_gcs
    blob.upload_from_filename(local_file)
  File "/home/airflow/.local/lib/python3.7/site-packages/google/cloud/storage/blob.py", line 2735, in upload_from_filename
    retry=retry,
  File "/home/airflow/.local/lib/python3.7/site-packages/google/cloud/storage/blob.py", line 2598, in upload_from_file
    _raise_from_invalid_response(exc)
  File "/home/airflow/.local/lib/python3.7/site-packages/google/cloud/storage/blob.py", line 4466, in _raise_from_invalid_response
    raise exceptions.from_http_status(response.status_code, message, response=response)
google.api_core.exceptions.NotFound: 404 POST https://storage.googleapis.com/upload/storage/v1/b/dtc_capstone_data_quiet-rigging-347402/o?uploadType=resumable: {
  "error": {
    "code": 404,
    "message": "The specified bucket does not exist.",
    "errors": [
      {
        "message": "The specified bucket does not exist.",
        "domain": "global",
        "reason": "notFound"
      }
    ]
  }
}
: ('Request failed with status code', 404, 'Expected one of', <HTTPStatus.OK: 200>, <HTTPStatus.CREATED: 201>)
[2022-04-28 01:10:05,446] {taskinstance.py:1277} INFO - Marking task as UP_FOR_RETRY. dag_id=local_2_gcs_2_bq_dag, task_id=people_local_to_gcs_task, execution_date=20220428T000000, start_date=20220428T011004, end_date=20220428T011005
[2022-04-28 01:10:05,512] {standard_task_runner.py:92} ERROR - Failed to execute job 10 for task people_local_to_gcs_task
Traceback (most recent call last):
  File "/home/airflow/.local/lib/python3.7/site-packages/google/cloud/storage/blob.py", line 2594, in upload_from_file
    retry=retry,
  File "/home/airflow/.local/lib/python3.7/site-packages/google/cloud/storage/blob.py", line 2412, in _do_upload
    retry=retry,
  File "/home/airflow/.local/lib/python3.7/site-packages/google/cloud/storage/blob.py", line 2237, in _do_resumable_upload
    retry=retry,
  File "/home/airflow/.local/lib/python3.7/site-packages/google/cloud/storage/blob.py", line 2112, in _initiate_resumable_upload
    timeout=timeout,
  File "/home/airflow/.local/lib/python3.7/site-packages/google/resumable_media/requests/upload.py", line 421, in initiate
    retriable_request, self._get_status_code, self._retry_strategy
  File "/home/airflow/.local/lib/python3.7/site-packages/google/resumable_media/requests/_request_helpers.py", line 147, in wait_and_retry
    response = func()
  File "/home/airflow/.local/lib/python3.7/site-packages/google/resumable_media/requests/upload.py", line 416, in retriable_request
    self._process_initiate_response(result)
  File "/home/airflow/.local/lib/python3.7/site-packages/google/resumable_media/_upload.py", line 503, in _process_initiate_response
    callback=self._make_invalid,
  File "/home/airflow/.local/lib/python3.7/site-packages/google/resumable_media/_helpers.py", line 104, in require_status_code
    *status_codes
google.resumable_media.common.InvalidResponse: ('Request failed with status code', 404, 'Expected one of', <HTTPStatus.OK: 200>, <HTTPStatus.CREATED: 201>)

During handling of the above exception, another exception occurred:

Traceback (most recent call last):
  File "/home/airflow/.local/lib/python3.7/site-packages/airflow/task/task_runner/standard_task_runner.py", line 85, in _start_by_fork
    args.func(args, dag=self.dag)
  File "/home/airflow/.local/lib/python3.7/site-packages/airflow/cli/cli_parser.py", line 48, in command
    return func(*args, **kwargs)
  File "/home/airflow/.local/lib/python3.7/site-packages/airflow/utils/cli.py", line 92, in wrapper
    return f(*args, **kwargs)
  File "/home/airflow/.local/lib/python3.7/site-packages/airflow/cli/commands/task_command.py", line 298, in task_run
    _run_task_by_selected_method(args, dag, ti)
  File "/home/airflow/.local/lib/python3.7/site-packages/airflow/cli/commands/task_command.py", line 107, in _run_task_by_selected_method
    _run_raw_task(args, ti)
  File "/home/airflow/.local/lib/python3.7/site-packages/airflow/cli/commands/task_command.py", line 184, in _run_raw_task
    error_file=args.error_file,
  File "/home/airflow/.local/lib/python3.7/site-packages/airflow/utils/session.py", line 70, in wrapper
    return func(*args, session=session, **kwargs)
  File "/home/airflow/.local/lib/python3.7/site-packages/airflow/models/taskinstance.py", line 1329, in _run_raw_task
    self._execute_task_with_callbacks(context)
  File "/home/airflow/.local/lib/python3.7/site-packages/airflow/models/taskinstance.py", line 1455, in _execute_task_with_callbacks
    result = self._execute_task(context, self.task)
  File "/home/airflow/.local/lib/python3.7/site-packages/airflow/models/taskinstance.py", line 1511, in _execute_task
    result = execute_callable(context=context)
  File "/home/airflow/.local/lib/python3.7/site-packages/airflow/operators/python.py", line 174, in execute
    return_value = self.execute_callable()
  File "/home/airflow/.local/lib/python3.7/site-packages/airflow/operators/python.py", line 185, in execute_callable
    return self.python_callable(*self.op_args, **self.op_kwargs)
  File "/opt/airflow/dags/download_2_gcs_dag_V2.py", line 48, in upload_to_gcs
    blob.upload_from_filename(local_file)
  File "/home/airflow/.local/lib/python3.7/site-packages/google/cloud/storage/blob.py", line 2735, in upload_from_filename
    retry=retry,
  File "/home/airflow/.local/lib/python3.7/site-packages/google/cloud/storage/blob.py", line 2598, in upload_from_file
    _raise_from_invalid_response(exc)
  File "/home/airflow/.local/lib/python3.7/site-packages/google/cloud/storage/blob.py", line 4466, in _raise_from_invalid_response
    raise exceptions.from_http_status(response.status_code, message, response=response)
google.api_core.exceptions.NotFound: 404 POST https://storage.googleapis.com/upload/storage/v1/b/dtc_capstone_data_quiet-rigging-347402/o?uploadType=resumable: {
  "error": {
    "code": 404,
    "message": "The specified bucket does not exist.",
    "errors": [
      {
        "message": "The specified bucket does not exist.",
        "domain": "global",
        "reason": "notFound"
      }
    ]
  }
}
: ('Request failed with status code', 404, 'Expected one of', <HTTPStatus.OK: 200>, <HTTPStatus.CREATED: 201>)
[2022-04-28 01:10:05,626] {local_task_job.py:154} INFO - Task exited with return code 1
[2022-04-28 01:10:05,910] {local_task_job.py:264} INFO - 0 downstream tasks scheduled from follow-on schedule check
[2022-04-28 01:56:36,825] {taskinstance.py:1032} INFO - Dependencies all met for <TaskInstance: local_2_gcs_2_bq_dag.people_local_to_gcs_task scheduled__2022-04-28T00:00:00+00:00 [queued]>
[2022-04-28 01:56:36,938] {taskinstance.py:1032} INFO - Dependencies all met for <TaskInstance: local_2_gcs_2_bq_dag.people_local_to_gcs_task scheduled__2022-04-28T00:00:00+00:00 [queued]>
[2022-04-28 01:56:36,945] {taskinstance.py:1238} INFO - 
--------------------------------------------------------------------------------
[2022-04-28 01:56:36,948] {taskinstance.py:1239} INFO - Starting attempt 1 of 2
[2022-04-28 01:56:36,950] {taskinstance.py:1240} INFO - 
--------------------------------------------------------------------------------
[2022-04-28 01:56:37,017] {taskinstance.py:1259} INFO - Executing <Task(PythonOperator): people_local_to_gcs_task> on 2022-04-28 00:00:00+00:00
[2022-04-28 01:56:37,051] {standard_task_runner.py:52} INFO - Started process 609 to run task
[2022-04-28 01:56:37,102] {standard_task_runner.py:76} INFO - Running: ['***', 'tasks', 'run', 'local_2_gcs_2_bq_dag', 'people_local_to_gcs_task', 'scheduled__2022-04-28T00:00:00+00:00', '--job-id', '10', '--raw', '--subdir', 'DAGS_FOLDER/download_2_gcs_dag_V2.py', '--cfg-path', '/tmp/tmpejl63iur', '--error-file', '/tmp/tmpk1kfz0cm']
[2022-04-28 01:56:37,118] {standard_task_runner.py:77} INFO - Job 10: Subtask people_local_to_gcs_task
[2022-04-28 01:56:37,583] {logging_mixin.py:109} INFO - Running <TaskInstance: local_2_gcs_2_bq_dag.people_local_to_gcs_task scheduled__2022-04-28T00:00:00+00:00 [running]> on host 1d2c8c1aba91
[2022-04-28 01:56:38,073] {taskinstance.py:1426} INFO - Exporting the following env vars:
AIRFLOW_CTX_DAG_OWNER=***
AIRFLOW_CTX_DAG_ID=local_2_gcs_2_bq_dag
AIRFLOW_CTX_TASK_ID=people_local_to_gcs_task
AIRFLOW_CTX_EXECUTION_DATE=2022-04-28T00:00:00+00:00
AIRFLOW_CTX_DAG_RUN_ID=scheduled__2022-04-28T00:00:00+00:00
[2022-04-28 02:00:56,742] {python.py:175} INFO - Done. Returned value was: None
[2022-04-28 02:00:56,801] {taskinstance.py:1277} INFO - Marking task as SUCCESS. dag_id=local_2_gcs_2_bq_dag, task_id=people_local_to_gcs_task, execution_date=20220428T000000, start_date=20220428T015636, end_date=20220428T020056
[2022-04-28 02:00:56,872] {local_task_job.py:154} INFO - Task exited with return code 0
[2022-04-28 02:00:56,967] {local_task_job.py:264} INFO - 0 downstream tasks scheduled from follow-on schedule check
